INFO:root:server.py >> Server is up and running! :D -- 2014-12-12 12:26:40.790000
INFO:root:server.py >> Client connected from: IPv4Address(TCP, '127.0.0.1', 45174) -- 2014-12-12 12:26:48.359000
INFO:root:server.py >> registering -- 2014-12-12 12:27:32.941000
INFO:root:server.py >> token successful for user: frank -- 2014-12-12 12:27:33.068000
INFO:root:server.py >> successfully created file for user frank -- 2014-12-12 12:29:33.798000
INFO:root:server.py >> successfully created file for user frank -- 2014-12-12 12:33:10.118000
INFO:root:server.py >> successfully deleted fileid ca554fd8ca082f6e94ddef250f9e461d1a3517489038b5a40f1c09d8259ad235 for user frank -- 2014-12-12 12:33:30.280000
INFO:root:server.py >> connection lost with client. reason: [Failure instance: Traceback (failure with no frames): <class 'twisted.internet.error.ConnectionLost'>: Connection to the other side was lost in a non-clean fashion: Connection lost.
] -- 2014-12-12 12:34:17.036000
INFO:root:server.py >> Server is up and running! :D -- 2014-12-12 12:44:14.227000
INFO:root:server.py >> Client connected from: IPv4Address(TCP, '127.0.0.1', 45293) -- 2014-12-12 12:44:24.122000
INFO:root:server.py >> registering -- 2014-12-12 12:44:38.213000
INFO:root:server.py >> token successful for user: daemon -- 2014-12-12 12:44:38.332000
INFO:root:server.py >> successfully created file for user daemon -- 2014-12-12 12:44:46.531000
INFO:root:server.py >> successfully created file for user daemon -- 2014-12-12 12:46:19.416000
INFO:root:server.py >> successfully wrote to fileid 71a4275f48e249915233b695b391a69059c573336a4e25e370a2b33becc8db5d for user daemon -- 2014-12-12 12:46:23.651000
INFO:root:server.py >> successfully deleted fileid 71a4275f48e249915233b695b391a69059c573336a4e25e370a2b33becc8db5d for user daemon -- 2014-12-12 12:46:34.777000
INFO:root:server.py >> successfully created file for user daemon -- 2014-12-12 12:46:38.711000
INFO:root:server.py >> successfully read fileid 1de8a11488ec39c9ff7e8acfa4fb1f29dd6ff49425f4c5f3f17f8b787d57826e for user daemon -- 2014-12-12 12:46:42.047000
INFO:root:server.py >> connection lost with client. reason: [Failure instance: Traceback (failure with no frames): <class 'twisted.internet.error.ConnectionLost'>: Connection to the other side was lost in a non-clean fashion: Connection lost.
] -- 2014-12-12 12:47:14.051000
INFO:root:server.py >> Server is up and running! :D -- 2014-12-12 12:49:24.029000
